<?xml version='1.0'?>
<sdf version="1.6">
  <model name="omnicopter">

    <pose>0 0 0.4 0 0 0</pose>
    <link name='base_link'>
      <velocity_decay>
        <linear>0.0</linear>
        <angular>0.0</angular>
      </velocity_decay>
      <inertial>
        <pose>0.009 0.005 0.006 0 0 0</pose>
        <mass>3.3</mass>
        <inertia>
          <ixx>0.13</ixx>
          <ixy>0.01</ixy>
          <ixz>0.01</ixz>
          <iyy>0.12</iyy>
          <iyz>0</iyz>
          <izz>0.2</izz>
        </inertia>
      </inertial>
      <collision name='base_link_collision'>
        <pose>0 0 0 0 0 0</pose>
        <geometry>
          <box>
            <size>0.47 0.47 0.55</size>
          </box>
        </geometry>
        <surface>
          <contact>
            <ode>
              <max_vel>10.0</max_vel>
              <min_depth>0.001</min_depth>
            </ode>
          </contact>
          <friction>
            <ode>
              <mu>1.0</mu>
              <mu2>1.0</mu2>
            </ode>
          </friction>
        </surface>
      </collision>
      <visual name='base_link_visual'>
        <geometry>
          <mesh>
            <uri>model://omnicopter/meshes/omni.stl</uri>
          </mesh>
        </geometry>
        <material>
          <script>
            <name>Gazebo/White</name>
          </script>
        </material>
      </visual>
	</link>
    <link name='imu_link'>
      <inertial>
        <pose>0 0 0 0 0 0</pose>
        <mass>0.02</mass>
        <inertia>
          <ixx>0.00001</ixx>
          <ixy>0</ixy>
          <ixz>0</ixz>
          <iyy>0.00002</iyy>
          <iyz>0</iyz>
          <izz>0.00002</izz>
        </inertia>
      </inertial>
      <sensor name="imu_sensor" type="imu">
        <pose>0 0 0 3.141593 0 0</pose>
        <always_on>1</always_on>
        <update_rate>1000.0</update_rate>
      </sensor>
    </link>
    <joint name='imu_joint' type='revolute'>
      <child>imu_link</child>
      <parent>base_link</parent>
      <axis>
        <xyz>0 0 1</xyz>
        <limit>
          <lower>0</lower>
          <upper>0</upper>
          <effort>0</effort>
          <velocity>0</velocity>
        </limit>
        <dynamics>
          <damping>1.0</damping>
        </dynamics>
        <use_parent_model_frame>1</use_parent_model_frame>
      </axis>
      <physics>
        <ode>
          <implicit_spring_damper>1</implicit_spring_damper>
        </ode>
      </physics>
    </joint>

<!-- FIND ROTORS -->
    <link name='rotor_0'>
      <pose>0.48374761 0.11400547 0.0  -1.85655318 -0.29207681 -0.21929448</pose>
      <inertial>
        <pose>0 0 0 0 -0 0</pose>
        <mass>0.015</mass>
        <inertia>
          <ixx>4.193333e-05</ixx>
          <ixy>0</ixy>
          <ixz>0</ixz>
          <iyy>4.193333e-05</iyy>
          <iyz>0</iyz>
          <izz>8.33e-05</izz>
        </inertia>
      </inertial>
      <collision name='rotor_0_collision'>
        <pose>0 0 0 0 -0 0</pose>
        <geometry>
          <cylinder>
            <length>0.005</length>
            <radius>0.06</radius>
          </cylinder>
        </geometry>
        <surface>
          <contact>
            <ode/>
          </contact>
          <friction>
            <ode/>
          </friction>
        </surface>
      </collision>
      <visual name='rotor_0_visual'>
        <pose>0 0 0 0 -0 0</pose>
        <geometry>
          <mesh>
            <scale>1 1 1</scale>
            <uri>model://omnicopter/meshes/CW.stl</uri>
          </mesh>
        </geometry>
        <material>
          <script>
            <name>Gazebo/Blue</name>
            <uri>__default__</uri>
          </script>
        </material>
      </visual>
      <gravity>1</gravity>
      <velocity_decay/>
      <self_collide>0</self_collide>
    </link>
    <joint name='rotor_0_joint' type='revolute'>
      <child>rotor_0</child>
      <parent>base_link</parent>
      <axis>
		<use_parent_model_frame>0</use_parent_model_frame>
        <xyz>0 0 1</xyz>
        <limit>
          <lower>-1e+16</lower>
          <upper>1e+16</upper>
        </limit>
        <dynamics>
          <damping>0.004</damping>
        </dynamics>
        <use_parent_model_frame>1</use_parent_model_frame>
      </axis>
      <physics>
        <ode>
          <implicit_spring_damper>1</implicit_spring_damper>
        </ode>
      </physics>
    </joint>
    <link name='rotor_1'>
      <pose>0.15621022 0.38314461 0.27533175 -0.78284715 -0.98303769 -2.70668811</pose>
      <inertial>
        <pose>0 0 0 0 -0 0</pose>
        <mass>0.015</mass>
        <inertia>
          <ixx>4.193333e-05</ixx>
          <ixy>0</ixy>
          <ixz>0</ixz>
          <iyy>4.193333e-05</iyy>
          <iyz>0</iyz>
          <izz>8.33e-05</izz>
        </inertia>
      </inertial>
      <collision name='rotor_1_collision'>
        <pose>0 0 0 0 -0 0</pose>
        <geometry>
          <cylinder>
            <length>0.005</length>
            <radius>0.06</radius>
          </cylinder>
        </geometry>
        <surface>
          <contact>
            <ode/>
          </contact>
          <friction>
            <ode/>
          </friction>
        </surface>
      </collision>
      <visual name='rotor_1_visual'>
        <pose>0 0 0 0 -0 0</pose>
        <geometry>
          <mesh>
            <scale>1 1 1</scale>
            <uri>model://omnicopter/meshes/CCW.stl</uri>
          </mesh>
        </geometry>
        <material>
          <script>
            <name>Gazebo/Blue</name>
            <uri>__default__</uri>
          </script>
        </material>
      </visual>
      <gravity>1</gravity>
      <velocity_decay/>
      <self_collide>0</self_collide>
    </link>
    <joint name='rotor_1_joint' type='revolute'>
      <child>rotor_1</child>
      <parent>base_link</parent>
      <axis>
		<use_parent_model_frame>0</use_parent_model_frame>
        <xyz>0 0 1</xyz>
        <limit>
          <lower>-1e+16</lower>
          <upper>1e+16</upper>
        </limit>
        <dynamics>
          <damping>0.004</damping>
        </dynamics>
        <use_parent_model_frame>1</use_parent_model_frame>
      </axis>
      <physics>
        <ode>
          <implicit_spring_damper>1</implicit_spring_damper>
        </ode>
      </physics>
    </joint>
    <link name='rotor_2'>
      <pose>-0.11032024 0.38136393 0.0 -0.33078502  0.84270089  2.99224844</pose>
      <inertial>
        <pose>0 0 0 0 -0 0</pose>
        <mass>0.015</mass>
        <inertia>
          <ixx>4.193333e-05</ixx>
          <ixy>0</ixy>
          <ixz>0</ixz>
          <iyy>4.193333e-05</iyy>
          <iyz>0</iyz>
          <izz>8.33e-05</izz>
        </inertia>
      </inertial>
      <collision name='rotor_2_collision'>
        <pose>0 0 0 0 -0 0</pose>
        <geometry>
          <cylinder>
            <length>0.005</length>
            <radius>0.06</radius>
          </cylinder>
        </geometry>
        <surface>
          <contact>
            <ode/>
          </contact>
          <friction>
            <ode/>
          </friction>
        </surface>
      </collision>
      <visual name='rotor_2_visual'>
        <pose>0 0 0 0 -0 0</pose>
        <geometry>
          <mesh>
            <scale>1 1 1</scale>
            <uri>model://omnicopter/meshes/CW.stl</uri>
          </mesh>
        </geometry>
        <material>
          <script>
            <name>Gazebo/Blue</name>
            <uri>__default__</uri>
          </script>
        </material>
      </visual>
      <gravity>1</gravity>
      <velocity_decay/>
      <self_collide>0</self_collide>
    </link>
    <joint name='rotor_2_joint' type='revolute'>
      <child>rotor_2</child>
      <parent>base_link</parent>
      <axis>
		<use_parent_model_frame>0</use_parent_model_frame>
        <xyz>0 0 1</xyz>
        <limit>
          <lower>-1e+16</lower>
          <upper>1e+16</upper>
        </limit>
        <dynamics>
          <damping>0.004</damping>
        </dynamics>
        <use_parent_model_frame>1</use_parent_model_frame>
      </axis>
      <physics>
        <ode>
          <implicit_spring_damper>1</implicit_spring_damper>
        </ode>
      </physics>
    </joint>
    <link name='rotor_3'>
      <pose>-0.35473328 0.25349615 0.0 2.6424989   0.32982685 -0.08477905</pose>
      <inertial>
        <pose>0 0 0 0 -0 0</pose>
        <mass>0.015</mass>
        <inertia>
          <ixx>4.193333e-05</ixx>
          <ixy>0</ixy>
          <ixz>0</ixz>
          <iyy>4.193333e-05</iyy>
          <iyz>0</iyz>
          <izz>8.33e-05</izz>
        </inertia>
      </inertial>
      <collision name='rotor_3_collision'>
        <pose>0 0 0 0 -0 0</pose>
        <geometry>
          <cylinder>
            <length>0.005</length>
            <radius>0.06</radius>
          </cylinder>
        </geometry>
        <surface>
          <contact>
            <ode/>
          </contact>
          <friction>
            <ode/>
          </friction>
        </surface>
      </collision>
      <visual name='rotor_3_visual'>
        <pose>0 0 0 0 -0 0</pose>
        <geometry>
          <mesh>
            <scale>1 1 1</scale>
            <uri>model://omnicopter/meshes/CCW.stl</uri>
          </mesh>
        </geometry>
        <material>
          <script>
            <name>Gazebo/Blue</name>
            <uri>__default__</uri>
          </script>
        </material>
      </visual>
      <gravity>1</gravity>
      <velocity_decay/>
      <self_collide>0</self_collide>
    </link>
    <joint name='rotor_3_joint' type='revolute'>
      <child>rotor_3</child>
      <parent>base_link</parent>
      <axis>
		<use_parent_model_frame>0</use_parent_model_frame>
        <xyz>0 0 1</xyz>
        <limit>
          <lower>-1e+16</lower>
          <upper>1e+16</upper>
        </limit>
        <dynamics>
          <damping>0.004</damping>
        </dynamics>
        <use_parent_model_frame>1</use_parent_model_frame>
      </axis>
      <physics>
        <ode>
          <implicit_spring_damper>1</implicit_spring_damper>
        </ode>
      </physics>
    </joint>
    <link name='rotor_4'>
      <pose>-0.41864087 -0.02021862 0.03964886 -1.84179685  0.07206257  0.05478069</pose>
      <inertial>
        <pose>0 0 0 0 -0 0</pose>
        <mass>0.015</mass>
        <inertia>
          <ixx>4.193333e-05</ixx>
          <ixy>0</ixy>
          <ixz>0</ixz>
          <iyy>4.193333e-05</iyy>
          <iyz>0</iyz>
          <izz>8.33e-05</izz>
        </inertia>
      </inertial>
      <collision name='rotor_4_collision'>
        <pose>0 0 0 0 -0 0</pose>
        <geometry>
          <cylinder>
            <length>0.005</length>
            <radius>0.06</radius>
          </cylinder>
        </geometry>
        <surface>
          <contact>
            <ode/>
          </contact>
          <friction>
            <ode/>
          </friction>
        </surface>
      </collision>
      <visual name='rotor_4_visual'>
        <pose>0 0 0 0 -0 0</pose>
        <geometry>
          <mesh>
            <scale>1 1 1</scale>
            <uri>model://omnicopter/meshes/CW.stl</uri>
          </mesh>
        </geometry>
        <material>
          <script>
            <name>Gazebo/Blue</name>
            <uri>__default__</uri>
          </script>
        </material>
      </visual>
      <gravity>1</gravity>
      <velocity_decay/>
      <self_collide>0</self_collide>
    </link>
    <joint name='rotor_4_joint' type='revolute'>
      <child>rotor_4</child>
      <parent>base_link</parent>
      <axis>
		<use_parent_model_frame>0</use_parent_model_frame>
        <xyz>0 0 1</xyz>
        <limit>
          <lower>-1e+16</lower>
          <upper>1e+16</upper>
        </limit>
        <dynamics>
          <damping>0.004</damping>
        </dynamics>
        <use_parent_model_frame>1</use_parent_model_frame>
      </axis>
      <physics>
        <ode>
          <implicit_spring_damper>1</implicit_spring_damper>
        </ode>
      </physics>
    </joint>
    <link name='rotor_5'>
      <pose>-0.12587546 -0.35639015 0.25151029 0.0098681   0.91727205 -3.13672024</pose>
      <inertial>
        <pose>0 0 0 0 -0 0</pose>
        <mass>0.015</mass>
        <inertia>
          <ixx>4.193333e-05</ixx>
          <ixy>0</ixy>
          <ixz>0</ixz>
          <iyy>4.193333e-05</iyy>
          <iyz>0</iyz>
          <izz>8.33e-05</izz>
        </inertia>
      </inertial>
      <collision name='rotor_5_collision'>
        <pose>0 0 0 0 -0 0</pose>
        <geometry>
          <cylinder>
            <length>0.005</length>
            <radius>0.06</radius>
          </cylinder>
        </geometry>
        <surface>
          <contact>
            <ode/>
          </contact>
          <friction>
            <ode/>
          </friction>
        </surface>
      </collision>
      <visual name='rotor_5_visual'>
        <pose>0 0 0 0 -0 0</pose>
        <geometry>
          <mesh>
            <scale>1 1 1</scale>
            <uri>model://omnicopter/meshes/CCW.stl</uri>
          </mesh>
        </geometry>
        <material>
          <script>
            <name>Gazebo/Blue</name>
            <uri>__default__</uri>
          </script>
        </material>
      </visual>
      <gravity>1</gravity>
      <velocity_decay/>
      <self_collide>0</self_collide>
    </link>
    <joint name='rotor_5_joint' type='revolute'>
      <child>rotor_5</child>
      <parent>base_link</parent>
      <axis>
		<use_parent_model_frame>0</use_parent_model_frame>
        <xyz>0 0 1</xyz>
        <limit>
          <lower>-1e+16</lower>
          <upper>1e+16</upper>
        </limit>
        <dynamics>
          <damping>0.004</damping>
        </dynamics>
        <use_parent_model_frame>1</use_parent_model_frame>
      </axis>
      <physics>
        <ode>
          <implicit_spring_damper>1</implicit_spring_damper>
        </ode>
      </physics>
    </joint>
    <link name='rotor_6'>
      <pose>0.22276892 -0.44427808 0.0 -0.37451244 -0.97919922 -2.94034096</pose>
      <inertial>
        <pose>0 0 0 0 -0 0</pose>
        <mass>0.015</mass>
        <inertia>
          <ixx>4.193333e-05</ixx>
          <ixy>0</ixy>
          <ixz>0</ixz>
          <iyy>4.193333e-05</iyy>
          <iyz>0</iyz>
          <izz>8.33e-05</izz>
        </inertia>
      </inertial>
      <collision name='rotor_6_collision'>
        <pose>0 0 0 0 -0 0</pose>
        <geometry>
          <cylinder>
            <length>0.005</length>
            <radius>0.06</radius>
          </cylinder>
        </geometry>
        <surface>
          <contact>
            <ode/>
          </contact>
          <friction>
            <ode/>
          </friction>
        </surface>
      </collision>
      <visual name='rotor_6_visual'>
        <pose>0 0 0 0 -0 0</pose>
        <geometry>
          <mesh>
            <scale>1 1 1</scale>
            <uri>model://omnicopter/meshes/CW.stl</uri>
          </mesh>
        </geometry>
        <material>
          <script>
            <name>Gazebo/Blue</name>
            <uri>__default__</uri>
          </script>
        </material>
      </visual>
      <gravity>1</gravity>
      <velocity_decay/>
      <self_collide>0</self_collide>
    </link>
    <joint name='rotor_6_joint' type='revolute'>
      <child>rotor_6</child>
      <parent>base_link</parent>
      <axis>
		<use_parent_model_frame>0</use_parent_model_frame>
        <xyz>0 0 1</xyz>
        <limit>
          <lower>-1e+16</lower>
          <upper>1e+16</upper>
        </limit>
        <dynamics>
          <damping>0.004</damping>
        </dynamics>
        <use_parent_model_frame>1</use_parent_model_frame>
      </axis>
      <physics>
        <ode>
          <implicit_spring_damper>1</implicit_spring_damper>
        </ode>
      </physics>
    </joint>
    <link name='rotor_7'>
      <pose>0.38490258 -0.17992486 0.13562099 2.4710711   0.01400798 -0.00488064</pose>
      <inertial>
        <pose>0 0 0 0 -0 0</pose>
        <mass>0.015</mass>
        <inertia>
          <ixx>4.193333e-05</ixx>
          <ixy>0</ixy>
          <ixz>0</ixz>
          <iyy>4.193333e-05</iyy>
          <iyz>0</iyz>
          <izz>8.33e-05</izz>
        </inertia>
      </inertial>
      <collision name='rotor_7_collision'>
        <pose>0 0 0 0 -0 0</pose>
        <geometry>
          <cylinder>
            <length>0.005</length>
            <radius>0.06</radius>
          </cylinder>
        </geometry>
        <surface>
          <contact>
            <ode/>
          </contact>
          <friction>
            <ode/>
          </friction>
        </surface>
      </collision>
      <visual name='rotor_7_visual'>
        <pose>0 0 0 0 -0 0</pose>
        <geometry>
          <mesh>
            <scale>1 1 1</scale>
            <uri>model://omnicopter/meshes/CCW.stl</uri>
          </mesh>
        </geometry>
        <material>
          <script>
            <name>Gazebo/Blue</name>
            <uri>__default__</uri>
          </script>
        </material>
      </visual>
      <gravity>1</gravity>
      <velocity_decay/>
      <self_collide>0</self_collide>
    </link>
    <joint name='rotor_7_joint' type='revolute'>
      <child>rotor_7</child>
      <parent>base_link</parent>
      <axis>
		<use_parent_model_frame>0</use_parent_model_frame>
        <xyz>0 0 1</xyz>
        <limit>
          <lower>-1e+16</lower>
          <upper>1e+16</upper>
        </limit>
        <dynamics>
          <damping>0.004</damping>
        </dynamics>
        <use_parent_model_frame>1</use_parent_model_frame>
      </axis>
      <physics>
        <ode>
          <implicit_spring_damper>1</implicit_spring_damper>
        </ode>
      </physics>
    </joint>


	<!-- Fix the pivot base to the world -->
<!--
	<link name="pivot"></link>
	<joint name="base_joint" type="fixed">
		<parent>world</parent>
		<child>pivot</child>
		<pose>0 0 2 0 0 0</pose>
	</joint>
	<joint name="ball_joint" type="ball">
		<parent>pivot</parent>
		<child>omnicopter::omnicopter/base_link</child>
	</joint>
-->

<!-- FIND PLUGINS -->

	<plugin name="odometry_sensor" filename="libodometry_plugin.so">
		<nameSpace>omnicopter</nameSpace>
	</plugin>

  	<plugin name="command_motors" filename="libbetacmd_motor_plugin.so">
  		<nameSpace>omnicopter</nameSpace>
  		<prop_num>8</prop_num>
  		<slowdown_sim>40</slowdown_sim>
  		<throttle>30000</throttle>
  		<thrust_const>4.4086e-06</thrust_const> 
  		<drag_const>0.001</drag_const>
  		<turning_directions>0 1 0 1 0 1 0 1</turning_directions>
  	</plugin>

	<!--

    <plugin name="betaflight_plugin" filename="libBetaflightPlugin.so">
      <imuName>imu_link::imu_sensor</imuName>
	  <mavName>omnicopter</mavName>
      <connectionTimeoutMaxCount>30</connectionTimeoutMaxCount>
      <rotor id="0">
        <vel_p_gain>0.01</vel_p_gain>
        <vel_i_gain>0</vel_i_gain>
        <vel_d_gain>0</vel_d_gain>
        <vel_i_max>0</vel_i_max>
        <vel_i_min>0</vel_i_min>
        <vel_cmd_max>2.0</vel_cmd_max>
        <vel_cmd_min>-2.0</vel_cmd_min>
        <jointName>omnicopter::rotor_0_joint</jointName>
        <turningDirection>cw</turningDirection>
        <rotorVelocitySlowdownSim>1</rotorVelocitySlowdownSim>
      </rotor>
      <rotor id="1">
        <vel_p_gain>0.01</vel_p_gain>
        <vel_i_gain>0</vel_i_gain>
        <vel_d_gain>0</vel_d_gain>
        <vel_i_max>0</vel_i_max>
        <vel_i_min>0</vel_i_min>
        <vel_cmd_max>2.0</vel_cmd_max>
        <vel_cmd_min>-2.0</vel_cmd_min>
        <jointName>omnicopter::rotor_1_joint</jointName>
        <turningDirection>cw</turningDirection>
        <rotorVelocitySlowdownSim>1</rotorVelocitySlowdownSim>
      </rotor>
      <rotor id="2">
        <vel_p_gain>0.01</vel_p_gain>
        <vel_i_gain>0</vel_i_gain>
        <vel_d_gain>0</vel_d_gain>
        <vel_i_max>0</vel_i_max>
        <vel_i_min>0</vel_i_min>
        <vel_cmd_max>2.0</vel_cmd_max>
        <vel_cmd_min>-2.0</vel_cmd_min>
        <jointName>omnicopter::rotor_2_joint</jointName>
        <turningDirection>cw</turningDirection>
        <rotorVelocitySlowdownSim>1</rotorVelocitySlowdownSim>
      </rotor>
      <rotor id="3">
        <vel_p_gain>0.01</vel_p_gain>
        <vel_i_gain>0</vel_i_gain>
        <vel_d_gain>0</vel_d_gain>
        <vel_i_max>0</vel_i_max>
        <vel_i_min>0</vel_i_min>
        <vel_cmd_max>2.0</vel_cmd_max>
        <vel_cmd_min>-2.0</vel_cmd_min>
        <jointName>omnicopter::rotor_3_joint</jointName>
        <turningDirection>cw</turningDirection>
        <rotorVelocitySlowdownSim>1</rotorVelocitySlowdownSim>
      </rotor>

      <rotor id="4">
        <vel_p_gain>0.01</vel_p_gain>
        <vel_i_gain>0</vel_i_gain>
        <vel_d_gain>0</vel_d_gain>
        <vel_i_max>0</vel_i_max>
        <vel_i_min>0</vel_i_min>
        <vel_cmd_max>2.0</vel_cmd_max>
        <vel_cmd_min>-2.0</vel_cmd_min>
        <jointName>omnicopter::rotor_4_joint</jointName>
        <turningDirection>cw</turningDirection>
        <rotorVelocitySlowdownSim>1</rotorVelocitySlowdownSim>
      </rotor>
      <rotor id="5">
        <vel_p_gain>0.01</vel_p_gain>
        <vel_i_gain>0</vel_i_gain>
        <vel_d_gain>0</vel_d_gain>
        <vel_i_max>0</vel_i_max>
        <vel_i_min>0</vel_i_min>
        <vel_cmd_max>2.0</vel_cmd_max>
        <vel_cmd_min>-2.0</vel_cmd_min>
        <jointName>omnicopter::rotor_5_joint</jointName>
        <turningDirection>cw</turningDirection>
        <rotorVelocitySlowdownSim>1</rotorVelocitySlowdownSim>
      </rotor>
      <rotor id="6">
        <vel_p_gain>0.01</vel_p_gain>
        <vel_i_gain>0</vel_i_gain>
        <vel_d_gain>0</vel_d_gain>
        <vel_i_max>0</vel_i_max>
        <vel_i_min>0</vel_i_min>
        <vel_cmd_max>2.0</vel_cmd_max>
        <vel_cmd_min>-2.0</vel_cmd_min>
        <jointName>omnicopter::rotor_6_joint</jointName>
        <turningDirection>cw</turningDirection>
        <rotorVelocitySlowdownSim>1</rotorVelocitySlowdownSim>
      </rotor>
      <rotor id="7">
        <vel_p_gain>0.01</vel_p_gain>
        <vel_i_gain>0</vel_i_gain>
        <vel_d_gain>0</vel_d_gain>
        <vel_i_max>0</vel_i_max>
        <vel_i_min>0</vel_i_min>
        <vel_cmd_max>2.0</vel_cmd_max>
        <vel_cmd_min>-2.0</vel_cmd_min>
        <jointName>omnicopter::rotor_7_joint</jointName>
        <turningDirection>cw</turningDirection>
        <rotorVelocitySlowdownSim>1</rotorVelocitySlowdownSim>
      </rotor>

    </plugin>
	-->


  </model>
</sdf>
